{
 "cells": [
  {
   "cell_type": "code",
   "execution_count": 7,
   "metadata": {},
   "outputs": [],
   "source": [
    "import numpy as np\n",
    "import pandas as pd\n",
    "import seaborn as sns\n",
    "import matplotlib.pyplot as plt"
   ]
  },
  {
   "cell_type": "code",
   "execution_count": 8,
   "metadata": {},
   "outputs": [
    {
     "name": "stderr",
     "output_type": "stream",
     "text": [
      "ERROR:root:Internal Python error in the inspect module.\n",
      "Below is the traceback from this internal error.\n",
      "\n"
     ]
    },
    {
     "name": "stdout",
     "output_type": "stream",
     "text": [
      "Traceback (most recent call last):\n",
      "  File \"/usr/lib/python3/dist-packages/IPython/core/interactiveshell.py\", line 3331, in run_code\n",
      "    exec(code_obj, self.user_global_ns, self.user_ns)\n",
      "  File \"<ipython-input-8-4afd86581cd1>\", line 1, in <module>\n",
      "    df = pd.read_csv(\"LeagueofLegends.csv\")\n",
      "  File \"/home/fatalvisor/.local/lib/python3.8/site-packages/pandas/util/_decorators.py\", line 311, in wrapper\n",
      "    return func(*args, **kwargs)\n",
      "  File \"/home/fatalvisor/.local/lib/python3.8/site-packages/pandas/io/parsers/readers.py\", line 680, in read_csv\n",
      "    return _read(filepath_or_buffer, kwds)\n",
      "  File \"/home/fatalvisor/.local/lib/python3.8/site-packages/pandas/io/parsers/readers.py\", line 575, in _read\n",
      "    parser = TextFileReader(filepath_or_buffer, **kwds)\n",
      "  File \"/home/fatalvisor/.local/lib/python3.8/site-packages/pandas/io/parsers/readers.py\", line 933, in __init__\n",
      "    self._engine = self._make_engine(f, self.engine)\n",
      "  File \"/home/fatalvisor/.local/lib/python3.8/site-packages/pandas/io/parsers/readers.py\", line 1217, in _make_engine\n",
      "    self.handles = get_handle(  # type: ignore[call-overload]\n",
      "  File \"/home/fatalvisor/.local/lib/python3.8/site-packages/pandas/io/common.py\", line 789, in get_handle\n",
      "    handle = open(\n",
      "FileNotFoundError: [Errno 2] No such file or directory: 'LeagueofLegends.csv'\n",
      "\n",
      "During handling of the above exception, another exception occurred:\n",
      "\n",
      "Traceback (most recent call last):\n",
      "  File \"/usr/lib/python3/dist-packages/IPython/core/interactiveshell.py\", line 2044, in showtraceback\n",
      "    stb = value._render_traceback_()\n",
      "AttributeError: 'FileNotFoundError' object has no attribute '_render_traceback_'\n",
      "\n",
      "During handling of the above exception, another exception occurred:\n",
      "\n",
      "Traceback (most recent call last):\n",
      "  File \"/usr/lib/python3/dist-packages/IPython/core/ultratb.py\", line 1148, in get_records\n",
      "    return _fixed_getinnerframes(etb, number_of_lines_of_context, tb_offset)\n",
      "  File \"/usr/lib/python3/dist-packages/IPython/core/ultratb.py\", line 316, in wrapped\n",
      "    return f(*args, **kwargs)\n",
      "  File \"/usr/lib/python3/dist-packages/IPython/core/ultratb.py\", line 350, in _fixed_getinnerframes\n",
      "    records = fix_frame_records_filenames(inspect.getinnerframes(etb, context))\n",
      "  File \"/usr/lib/python3.8/inspect.py\", line 1515, in getinnerframes\n",
      "    frameinfo = (tb.tb_frame,) + getframeinfo(tb, context)\n",
      "  File \"/usr/lib/python3.8/inspect.py\", line 1473, in getframeinfo\n",
      "    filename = getsourcefile(frame) or getfile(frame)\n",
      "  File \"/usr/lib/python3.8/inspect.py\", line 708, in getsourcefile\n",
      "    if getattr(getmodule(object, filename), '__loader__', None) is not None:\n",
      "  File \"/usr/lib/python3.8/inspect.py\", line 737, in getmodule\n",
      "    file = getabsfile(object, _filename)\n",
      "  File \"/usr/lib/python3.8/inspect.py\", line 721, in getabsfile\n",
      "    return os.path.normcase(os.path.abspath(_filename))\n",
      "  File \"/usr/lib/python3.8/posixpath.py\", line 379, in abspath\n",
      "    cwd = os.getcwd()\n",
      "FileNotFoundError: [Errno 2] No such file or directory\n"
     ]
    },
    {
     "ename": "FileNotFoundError",
     "evalue": "[Errno 2] No such file or directory: 'LeagueofLegends.csv'",
     "output_type": "error",
     "traceback": [
      "\u001b[0;31m---------------------------------------------------------------------------\u001b[0m"
     ]
    }
   ],
   "source": [
    "df = pd.read_csv(\"LeagueofLegends.csv\")\n",
    "df.head()"
   ]
  }
 ],
 "metadata": {
  "language_info": {
   "name": "python"
  },
  "orig_nbformat": 4
 },
 "nbformat": 4,
 "nbformat_minor": 2
}
